1. you didn't set up chrome for spider 

----------------------------------------------------------------------------------------------------------------
Error in sys.excepthook:
TypeError: 'NoneType' object is not callable

Original exception was:
Traceback (most recent call last):
  File "C:\Users\shijonn\Desktop\venv\lib\site-packages\urllib3\connection.py", line 160, in _new_conn
    (self._dns_host, self.port), self.timeout, **extra_kw)
  File "C:\Users\shijonn\Desktop\venv\lib\site-packages\urllib3\util\connection.py", line 80, in create_connection
    raise err
  File "C:\Users\shijonn\Desktop\venv\lib\site-packages\urllib3\util\connection.py", line 70, in create_connection
    sock.connect(sa)
ConnectionRefusedError: [WinError 10061] No connection could be made because the target machine actively refused it

During handling of the above exception, another exception occurred:

Traceback (most recent call last):
  File "C:\Users\shijonn\Desktop\venv\lib\site-packages\urllib3\connectionpool.py", line 603, in urlopen
    chunked=chunked)
  File "C:\Users\shijonn\Desktop\venv\lib\site-packages\urllib3\connectionpool.py", line 355, in _make_request
    conn.request(method, url, **httplib_request_kw)
  File "c:\anaconda3\Lib\http\client.py", line 1229, in request
    self._send_request(method, url, body, headers, encode_chunked)
  File "c:\anaconda3\Lib\http\client.py", line 1275, in _send_request
    self.endheaders(body, encode_chunked=encode_chunked)
  File "c:\anaconda3\Lib\http\client.py", line 1224, in endheaders
    self._send_output(message_body, encode_chunked=encode_chunked)
  File "c:\anaconda3\Lib\http\client.py", line 1016, in _send_output
    self.send(msg)
  File "c:\anaconda3\Lib\http\client.py", line 956, in send
    self.connect()
  File "C:\Users\shijonn\Desktop\venv\lib\site-packages\urllib3\connection.py", line 183, in connect
    conn = self._new_conn()
  File "C:\Users\shijonn\Desktop\venv\lib\site-packages\urllib3\connection.py", line 169, in _new_conn
    self, "Failed to establish a new connection: %s" % e)
urllib3.exceptions.NewConnectionError: <urllib3.connection.HTTPConnection object at 0x00000279A94C1588>: Failed to establish a new connection: [WinError 10061] No connection could be made because the target machine actively refused it

During handling of the above exception, another exception occurred:

Traceback (most recent call last):
  File "C:\Users\shijonn\Desktop\venv\lib\site-packages\requests\adapters.py", line 449, in send
    timeout=timeout
  File "C:\Users\shijonn\Desktop\venv\lib\site-packages\urllib3\connectionpool.py", line 641, in urlopen
    _stacktrace=sys.exc_info()[2])
  File "C:\Users\shijonn\Desktop\venv\lib\site-packages\urllib3\util\retry.py", line 399, in increment
    raise MaxRetryError(_pool, url, error or ResponseError(cause))
urllib3.exceptions.MaxRetryError: HTTPConnectionPool(host='127.0.0.1', port=9222): Max retries exceeded with url: /json/new (Caused by NewConnectionError('<urllib3.connection.HTTPConnection object at 0x00000279A94C1588>: Failed to establish a new connection: [WinError 10061] No connection could be made because the target machine actively refused it'))

During handling of the above exception, another exception occurred:

Traceback (most recent call last):
  File "Remote-Monitoring-Platform.py", line 31, in call_web
    tab = browser.new_tab()
  File "C:\Users\shijonn\Desktop\venv\lib\site-packages\pychrome\browser.py", line 27, in new_tab
    rp = requests.get("%s/json/new?%s" % (self.dev_url, url), json=True, timeout=timeout)
  File "C:\Users\shijonn\Desktop\venv\lib\site-packages\requests\api.py", line 75, in get
    return request('get', url, params=params, **kwargs)
  File "C:\Users\shijonn\Desktop\venv\lib\site-packages\requests\api.py", line 60, in request
    return session.request(method=method, url=url, **kwargs)
  File "C:\Users\shijonn\Desktop\venv\lib\site-packages\requests\sessions.py", line 533, in request
    resp = self.send(prep, **send_kwargs)
  File "C:\Users\shijonn\Desktop\venv\lib\site-packages\requests\sessions.py", line 646, in send
    r = adapter.send(request, **kwargs)
  File "C:\Users\shijonn\Desktop\venv\lib\site-packages\requests\adapters.py", line 516, in send
    raise ConnectionError(e, request=request)
requests.exceptions.ConnectionError: HTTPConnectionPool(host='127.0.0.1', port=9222): Max retries exceeded with url: /json/new (Caused by NewConnectionError('<urllib3.connection.HTTPConnection object at 0x00000279A94C1588>: Failed to establish a new connection: [WinError 10061] No connection could be made because the target machine actively refused it'))
Error in sys.excepthook:
TypeError: 'NoneType' object is not callable

Original exception was:
Traceback (most recent call last):
  File "C:\Users\shijonn\Desktop\venv\lib\site-packages\urllib3\connection.py", line 160, in _new_conn
    (self._dns_host, self.port), self.timeout, **extra_kw)
  File "C:\Users\shijonn\Desktop\venv\lib\site-packages\urllib3\util\connection.py", line 80, in create_connection
    raise err
  File "C:\Users\shijonn\Desktop\venv\lib\site-packages\urllib3\util\connection.py", line 70, in create_connection
    sock.connect(sa)
ConnectionRefusedError: [WinError 10061] No connection could be made because the target machine actively refused it

During handling of the above exception, another exception occurred:

Traceback (most recent call last):
  File "C:\Users\shijonn\Desktop\venv\lib\site-packages\urllib3\connectionpool.py", line 603, in urlopen
    chunked=chunked)
  File "C:\Users\shijonn\Desktop\venv\lib\site-packages\urllib3\connectionpool.py", line 355, in _make_request
    conn.request(method, url, **httplib_request_kw)
  File "c:\anaconda3\Lib\http\client.py", line 1229, in request
    self._send_request(method, url, body, headers, encode_chunked)
  File "c:\anaconda3\Lib\http\client.py", line 1275, in _send_request
    self.endheaders(body, encode_chunked=encode_chunked)
  File "c:\anaconda3\Lib\http\client.py", line 1224, in endheaders
    self._send_output(message_body, encode_chunked=encode_chunked)
  File "c:\anaconda3\Lib\http\client.py", line 1016, in _send_output
    self.send(msg)
  File "c:\anaconda3\Lib\http\client.py", line 956, in send
    self.connect()
  File "C:\Users\shijonn\Desktop\venv\lib\site-packages\urllib3\connection.py", line 183, in connect
    conn = self._new_conn()
  File "C:\Users\shijonn\Desktop\venv\lib\site-packages\urllib3\connection.py", line 169, in _new_conn
    self, "Failed to establish a new connection: %s" % e)
urllib3.exceptions.NewConnectionError: <urllib3.connection.HTTPConnection object at 0x00000279A94C1CF8>: Failed to establish a new connection: [WinError 10061] No connection could be made because the target machine actively refused it

During handling of the above exception, another exception occurred:

Traceback (most recent call last):
  File "C:\Users\shijonn\Desktop\venv\lib\site-packages\requests\adapters.py", line 449, in send
    timeout=timeout
  File "C:\Users\shijonn\Desktop\venv\lib\site-packages\urllib3\connectionpool.py", line 641, in urlopen
    _stacktrace=sys.exc_info()[2])
  File "C:\Users\shijonn\Desktop\venv\lib\site-packages\urllib3\util\retry.py", line 399, in increment
    raise MaxRetryError(_pool, url, error or ResponseError(cause))
urllib3.exceptions.MaxRetryError: HTTPConnectionPool(host='127.0.0.1', port=9222): Max retries exceeded with url: /json/new (Caused by NewConnectionError('<urllib3.connection.HTTPConnection object at 0x00000279A94C1CF8>: Failed to establish a new connection: [WinError 10061] No connection could be made because the target machine actively refused it'))

During handling of the above exception, another exception occurred:

Traceback (most recent call last):
  File "Remote-Monitoring-Platform.py", line 31, in call_web
    tab = browser.new_tab()
  File "C:\Users\shijonn\Desktop\venv\lib\site-packages\pychrome\browser.py", line 27, in new_tab
    rp = requests.get("%s/json/new?%s" % (self.dev_url, url), json=True, timeout=timeout)
  File "C:\Users\shijonn\Desktop\venv\lib\site-packages\requests\api.py", line 75, in get
    return request('get', url, params=params, **kwargs)
  File "C:\Users\shijonn\Desktop\venv\lib\site-packages\requests\api.py", line 60, in request
    return session.request(method=method, url=url, **kwargs)
  File "C:\Users\shijonn\Desktop\venv\lib\site-packages\requests\sessions.py", line 533, in request
    resp = self.send(prep, **send_kwargs)
  File "C:\Users\shijonn\Desktop\venv\lib\site-packages\requests\sessions.py", line 646, in send
    r = adapter.send(request, **kwargs)
  File "C:\Users\shijonn\Desktop\venv\lib\site-packages\requests\adapters.py", line 516, in send
    raise ConnectionError(e, request=request)
requests.exceptions.ConnectionError: HTTPConnectionPool(host='127.0.0.1', port=9222): Max retries exceeded with url: /json/new (Caused by NewConnectionError('<urllib3.connection.HTTPConnection object at 0x00000279A94C1CF8>: Failed to establish a new connection: [WinError 10061] No connection could be made because the target machine actively refused it'))

-----------------------------------------------------------------------------------------------------------------------------------------------